Traceback (most recent call last):
  File "c:\users\emsuewil\anaconda3\envs\stats_for_hds\lib\site-packages\jupyter_cache\executors\utils.py", line 56, in single_nb_execution
    record_timing=False,
  File "c:\users\emsuewil\anaconda3\envs\stats_for_hds\lib\site-packages\nbclient\client.py", line 1077, in execute
    return NotebookClient(nb=nb, resources=resources, km=km, **kwargs).execute()
  File "c:\users\emsuewil\anaconda3\envs\stats_for_hds\lib\site-packages\nbclient\util.py", line 74, in wrapped
    return just_run(coro(*args, **kwargs))
  File "c:\users\emsuewil\anaconda3\envs\stats_for_hds\lib\site-packages\nbclient\util.py", line 53, in just_run
    return loop.run_until_complete(coro)
  File "c:\users\emsuewil\anaconda3\envs\stats_for_hds\lib\asyncio\base_events.py", line 573, in run_until_complete
    return future.result()
  File "c:\users\emsuewil\anaconda3\envs\stats_for_hds\lib\site-packages\nbclient\client.py", line 527, in async_execute
    cell, index, execution_count=self.code_cells_executed + 1
  File "c:\users\emsuewil\anaconda3\envs\stats_for_hds\lib\site-packages\nbclient\client.py", line 822, in async_execute_cell
    self._check_raise_for_error(cell, exec_reply)
  File "c:\users\emsuewil\anaconda3\envs\stats_for_hds\lib\site-packages\nbclient\client.py", line 730, in _check_raise_for_error
    raise CellExecutionError.from_cell_and_msg(cell, exec_reply['content'])
nbclient.exceptions.CellExecutionError: An error occurred while executing the following cell:
------------------
# first we estimate the null model
dementia0 <- glm(dementia ~ 1, data = dementia, family = binomial(link="logit")) 

# then we compute the McFadden pseudo-R2 for each model
R2_McFadden1 <- as.double(1 - logLik(dementia1)/logLik(dementia0))
R2_McFadden2 <- as.double(1 - logLik(dementia2)/logLik(dementia0))
R2_McFadden3 <- as.double(1 - logLik(dementia3)/logLik(dementia0))

round(c("model 1" = R2_McFadden1, "model 2" = R2_McFadden2, "model 3" = R2_McFadden3),3)
------------------

Error in is.data.frame(data): object 'dementia' not found
Traceback:

1. glm(dementia ~ 1, data = dementia, family = binomial(link = "logit"))
2. eval(mf, parent.frame())
3. eval(mf, parent.frame())
4. stats::model.frame(formula = dementia ~ 1, data = dementia, drop.unused.levels = TRUE)
5. model.frame.default(formula = dementia ~ 1, data = dementia, 
 .     drop.unused.levels = TRUE)
6. is.data.frame(data)
ERROR: Error in is.data.frame(data): object 'dementia' not found


